<?xml version="1.0"?>

<robot xmlns:drake="http://drake.mit.edu" name="irb1200">
    <link name="base">
        <inertial>
            <origin xyz="0 0 0.102303" rpy="0 0 0"/>
            <mass value="77.709167"/>
            <inertia ixx="100"  ixy="0"  ixz="0" iyy="100" iyz="0" izz="100" />
        </inertial>
        <visual>
            <origin xyz="-0.192904 -0.118714 0" rpy ="0 0 0" />
            <geometry>
                <mesh filename="meshes/base_stan.obj" scale="0.001"/>
            </geometry>
            <material name="abb_grey">
                <color rgba = "0.945 0.945 0.945 1.0"/>
            </material>
        </visual>
    </link>

    <link name="swing">
        <inertial>
            <origin xyz="0 0 0.5" rpy="0 0 0"/>
            <mass value="44.279755"/>
            <inertia ixx="0.553503"  ixy="0"  ixz="0" iyy="0.3509" iyz="0" izz="0.403" />
        </inertial>
        <visual>
            <origin xyz="-0.129879 -0.137376 -0.219" rpy ="0 0 0" />
            <geometry>
                <mesh filename="meshes/swing.obj" scale="0.001"/>
            </geometry>
            <material name="abb_grey"/>
        </visual>
    </link>

    <link name="lower_arm">
        <inertial>
            <origin xyz="-0.012333 0 0.218482" rpy="0 0 0"/>
            <mass value="58.205945"/>
            <inertia ixx="1.948755"  ixy="0"  ixz="0" iyy="1.786429" iyz="0" izz="0.315341" />
        </inertial>
        <visual>
            <origin xyz="-0.082437 -0.120644 -0.39912" rpy ="0 0 0" />
            <geometry>
                <mesh filename="meshes/lower arm_900.obj" scale="0.001"/>
            </geometry>
            <material name="abb_grey"/>
        </visual>
    </link>

    <link name="housing">
        <inertial>
            <origin xyz="0.0979 0 0.0348" rpy="0 0 0"/>
            <mass value="46.942720"/>
            <inertia ixx="0.149"  ixy="0"  ixz="0" iyy="0.573" iyz="0" izz="0.5279" />
        </inertial>
        <visual>
            <origin xyz="-0.092996 -0.062198 -0.846826" rpy ="0 0 0" />
            <geometry>
                <mesh filename="meshes/housing_900.obj" scale="0.001"/>
            </geometry>
            <material name="abb_grey"/>
        </visual>
    </link>

    <link name="tubular">
        <inertial>
            <origin xyz="0.076246 0 0" rpy="0 0 0"/>
            <mass value="12.158346"/>
            <inertia ixx="0.025960"  ixy="0.001753"  ixz="0" iyy="0.045991" iyz="0" izz="0.049850" />
        </inertial>
        <visual>
            <origin xyz="-0.2885 -0.061289 -0.889055" rpy ="0 0 0" />
            <geometry>
                <mesh filename="meshes/tubular_(900).obj" scale="0.001"/>
            </geometry>
            <material name="abb_grey"/>
        </visual>
    </link>

    <link name="tilt">
        <inertial>
            <origin xyz="0.008399 0 0" rpy="0 0 0"/>
            <mass value="3.705306"/>
            <inertia ixx="0.002742"  ixy="0"  ixz="0" iyy="0.006361" iyz="0" izz="0.005330" />
        </inertial>
        <visual>
            <origin xyz="-0.451 -0.0325 -0.889100" rpy ="0 0 0" />
            <geometry>
                <mesh filename="meshes/tilt_(900)_Non-foundry option.obj" scale="0.001"/>
            </geometry>
            <material name="abb_grey"/>
        </visual>
    </link>

    <link name="disk">
        <inertial>
            <origin xyz="0.00248 0 0" rpy="0 0 0"/>
            <mass value="0.03"/>
            <inertia ixx="0.00000783"  ixy="0"  ixz="0" iyy="0.00000389" iyz="0" izz="0.00000407" />
        </inertial>
        <visual>
            <origin xyz="-0.528 -0.02 -0.889100" rpy ="0 0 0" />
            <geometry>
                <mesh filename="meshes/disk_(900).obj" scale="0.001"/>
            </geometry>
            <material name="abb_grey"/>
        </visual>
    </link>

    <link name="gripper_frame">
        <inertial>
            <origin xyz="0 0 0" rpy="0 0 0"/>
            <mass value="0.001"/>
            <inertia ixx="0.00000001" ixy="0" ixz="0" iyy="0.00000001" iyz="0" izz="0.00000001"/>
        </inertial>
    </link>

    <joint name="base_swing_revolute" type="revolute">
        <origin xyz="0 0 0.219"/>
        <parent link="base"/>
        <child link="swing"/>
        <axis xyz="0 0 1"/>
        <limit lower="-2.96" upper="2.96" effort="1000" velocity="5.0"/>
    </joint>

    <transmission name="base_swing_transmission">
        <type>transmission_interface/SimpleTransmission</type>
        <joint name="base_swing_revolute"/>
        <actuator name="base_swing_actuator"/>
    </transmission>

    <joint name="swing_lower_arm_revolute" type="revolute">
        <origin xyz="0 0 0.1801"/>
        <parent link="swing"/>
        <child link="lower_arm"/>
        <axis xyz="0 1 0"/>
        <limit lower="-1.74" upper="2.26" effort="1000" velocity="4.18"/>
    </joint>

    <transmission name="swing_lower_arm_transmission">
        <type>transmission_interface/SimpleTransmission</type>
        <joint name="swing_lower_arm_revolute"/>
        <actuator name="swing_lower_arm_actuator"/>
    </transmission>

    <joint name="lower_arm_housing_revolute" type="revolute">
        <origin xyz="0 0 0.448"/>
        <parent link="lower_arm"/>
        <child link="housing"/>
        <axis xyz="0 1 0"/>
        <limit lower="-3.49" upper="1.22" effort="1000" velocity="5.18"/>
    </joint>

    <transmission name="lower_arm_housing_transmission">
        <type>transmission_interface/SimpleTransmission</type>
        <joint name="lower_arm_housing_revolute"/>
        <actuator name="lower_arm_housing_actuator"/>
    </transmission>

    <joint name="housing_tubular_revolute" type="revolute">
        <origin xyz="0.2885 0 0.042056"/>
        <parent link="housing"/>
        <child link="tubular"/>
        <axis xyz="1 0 0"/>
        <limit lower="-4.71" upper="4.71" effort="1000" velocity="6.98"/>
    </joint>

    <transmission name="housing_tubular_transmission">
        <type>transmission_interface/SimpleTransmission</type>
        <joint name="housing_tubular_revolute"/>
        <actuator name="housing_tubular_actuator"/>
    </transmission>

    <joint name="tubular_tilt_revolute" type="revolute">
        <origin xyz="0.1625 0 0"/>
        <parent link="tubular"/>
        <child link="tilt"/>
        <axis xyz="0 1 0"/>
        <limit lower="-2.26" upper="2.26" effort="1000" velocity="7.06"/>
    </joint>

    <transmission name="tubular_tilt_transmission">
        <type>transmission_interface/SimpleTransmission</type>
        <joint name="tubular_tilt_revolute"/>
        <actuator name="tubular_tilt_actuator"/>
    </transmission>

    <joint name="tilt_disk_revolute" type="revolute">
        <origin xyz="0.077 0 0"/>
        <parent link="tilt"/>
        <child link="disk"/>
        <axis xyz="1 0 0"/>
        <limit lower="-6.98" upper="6.98" effort="1000" velocity="10.47"/>
    </joint>

    <transmission name="tilt_disk_transmission">
        <type>transmission_interface/SimpleTransmission</type>
        <joint name="tilt_disk_revolute"/>
        <actuator name="tilt_disk_actuator"/>
    </transmission>

    <joint name="disk_gripper_frame_fixed" type="fixed">
        <origin xyz="0 0 0" rpy="3.14159265359 -1.57079632679 0"/>
        <parent link="disk"/>
        <child link="gripper_frame"/>
    </joint>

</robot>